Workbook

Sheet README
A1: Formula-only complaint classification: three ways, no Python, no add-ins
A3: Sheets
A4: Complaints | B4: The 900 sample complaints (id, text, true label).
A5: Rules | B5: 59 hand-written keywords with weights, plus the settings (min score, min margin) in H1:H2. Columns D and E are the match patterns.
A6: Terms | B6: The frozen model's learned word and word-pair weights (819 rows x 6 categories) plus an intercept row. Exported from the TF-IDF + logistic regression model, trained with seed 42.
A7: Scored | B7: One row per complaint. Columns E to K: exact keyword scoring. L to R: fuzzy (word-stem) keyword scoring. S to Y: scoring with the learned weights.
A9: How to read it
A10: Every label is a formula. The same inputs give the same label every time. To freeze: copy the label columns and Paste Special > Values onto a new sheet.
A11: The learned-weights route is an approximation of the Python model (it matches words as written, without the model's stop-word removal and length scaling). It agrees with the Python model on about 94% of held-out complaints.
A12: New, NewComplaints, Answers | B12: 200 brand-new complaints scored by formulas: keyword rules (exact), the learned weights, and rules first then learned weights. The Answers sheet holds the true labels so the New sheet can mark each label right or wrong. In real life you would not have the answers yet.
A13: Column Z says whether the complaint was in the 720 the model learned from (train) or the 180 it did not see (test). Quote accuracy for the learned route on test rows only.

Sheet Complaints
A1: complaint_id | B1: text | C1: true_label
A2: C0001 | B2: I was told this policy overed me but my claim was rejected. Also, the complaints handler was unhelpful and talked over me. This is not acceptable. | C2: Mis-selling
A3: C0002 | B3: Hello, I was told this policy covered me but my claim was rejected. I could not log in to check either. | C3: Mis-selling
A4: C0003 | B4: This is the second time I have raised this. The salesperson pushed me into a plan I did not need. I could not log in to check either. I would like a response in writing. | C4: Mis-selling
A5: C0004 | B5: I am writing to complain. It has taken six weeks to process my claim and nobody has updated me. Please sort this out. | C5: Delays & Processing
A6: C0005 | B6: My mortgage switch is taking far longer than you said it would. Please escalate this. | C6: Delays & Processing
A7: C0006 | B7: Hello, The app crashes every time I try to open my statements. There was also a fee involved. I expect compensation. | C7: Account Access
A8: C0007 | B8: This is the second time I have raised this. The brochure said guaranteed returns and my money has lost value. I also spent ages on hold when I called about it. Please sort this out. | C8: Mis-selling
A9: C0008 | B9: This is the second time I have raised this. I asked for a callback and it never happened. I would like a response in writing. | C9: Customer Service
A10: C0009 | B10: I am writing to complain. Why has my interest rate gone up without notice, it is costing me more every month. | C10: Fees & Charges
A11: C0010 | B11: To whom it may concern, Someone has made payments from my account that I did not authorise. Also, the app crashes every time I try to open my statements. Please escalate this. | C11: Fraud & Scams
A12: C0011 | B12: I was tricked into moving savings to a safe account that was not safe. Also, my account was frozen and I cannot get in to move money. | C12: Fraud & Scams
... A901: C0900 | B901: Hello, I spent an hour on hold and then the call was cut off. Also, the account maintenance fee was taken twice this month. | C901: Customer Service

Sheet Rules
A1: category | B1: keyword | C1: weight | D1: exact_pattern | E1: fuzzy_pattern | G1: min_score | H1: 3
A2: Fees & Charges | B2: fee | C2: 2 | D2: =" "&B2&" " -> fee | E2: =IF(OR(ISNUMBER(SEARCH(" ",B2)),LEN(B2)<6)," "&B2&" "," "&LEFT(B2,LEN(B2)-2)) -> fee | G2: min_margin | H2: 2
A3: Fees & Charges | B3: charge | C3: 2 | D3: =" "&B3&" " -> charge | E3: =IF(OR(ISNUMBER(SEARCH(" ",B3)),LEN(B3)<6)," "&B3&" "," "&LEFT(B3,LEN(B3)-2)) -> char
A4: Fees & Charges | B4: charged | C4: 2 | D4: =" "&B4&" " -> charged | E4: =IF(OR(ISNUMBER(SEARCH(" ",B4)),LEN(B4)<6)," "&B4&" "," "&LEFT(B4,LEN(B4)-2)) -> charg
A5: Fees & Charges | B5: billed | C5: 2 | D5: =" "&B5&" " -> billed | E5: =IF(OR(ISNUMBER(SEARCH(" ",B5)),LEN(B5)<6)," "&B5&" "," "&LEFT(B5,LEN(B5)-2)) -> bill
A6: Fees & Charges | B6: penalty | C6: 2 | D6: =" "&B6&" " -> penalty | E6: =IF(OR(ISNUMBER(SEARCH(" ",B6)),LEN(B6)<6)," "&B6&" "," "&LEFT(B6,LEN(B6)-2)) -> penal
A7: Fees & Charges | B7: interest rate | C7: 2 | D7: =" "&B7&" " -> interest rate | E7: =IF(OR(ISNUMBER(SEARCH(" ",B7)),LEN(B7)<6)," "&B7&" "," "&LEFT(B7,LEN(B7)-2)) -> interest rate
A8: Fees & Charges | B8: costs | C8: 1 | D8: =" "&B8&" " -> costs | E8: =IF(OR(ISNUMBER(SEARCH(" ",B8)),LEN(B8)<6)," "&B8&" "," "&LEFT(B8,LEN(B8)-2)) -> costs
A9: Fees & Charges | B9: statement | C9: 1 | D9: =" "&B9&" " -> statement | E9: =IF(OR(ISNUMBER(SEARCH(" ",B9)),LEN(B9)<6)," "&B9&" "," "&LEFT(B9,LEN(B9)-2)) -> stateme
A10: Delays & Processing | B10: pending | C10: 2 | D10: =" "&B10&" " -> pending | E10: =IF(OR(ISNUMBER(SEARCH(" ",B10)),LEN(B10)<6)," "&B10&" "," "&LEFT(B10,LEN(B10)-2)) -> pendi
A11: Delays & Processing | B11: delayed | C11: 2 | D11: =" "&B11&" " -> delayed | E11: =IF(OR(ISNUMBER(SEARCH(" ",B11)),LEN(B11)<6)," "&B11&" "," "&LEFT(B11,LEN(B11)-2)) -> delay
A12: Delays & Processing | B12: weeks | C12: 1 | D12: =" "&B12&" " -> weeks | E12: =IF(OR(ISNUMBER(SEARCH(" ",B12)),LEN(B12)<6)," "&B12&" "," "&LEFT(B12,LEN(B12)-2)) -> weeks
A13: Delays & Processing | B13: waiting | C13: 2 | D13: =" "&B13&" " -> waiting | E13: =IF(OR(ISNUMBER(SEARCH(" ",B13)),LEN(B13)<6)," "&B13&" "," "&LEFT(B13,LEN(B13)-2)) -> waiti
A14: Delays & Processing | B14: outstanding | C14: 2 | D14: =" "&B14&" " -> outstanding | E14: =IF(OR(ISNUMBER(SEARCH(" ",B14)),LEN(B14)<6)," "&B14&" "," "&LEFT(B14,LEN(B14)-2)) -> outstandi
... A60: Account Access | B60: crashes | C60: 2 | D60: =" "&B60&" " -> crashes | E60: =IF(OR(ISNUMBER(SEARCH(" ",B60)),LEN(B60)<6)," "&B60&" "," "&LEFT(B60,LEN(B60)-2)) -> crash

Sheet Terms
A1: term | B1: Account Access | C1: Customer Service | D1: Delays & Processing | E1: Fees & Charges | F1: Fraud & Scams | G1: Mis-selling
A2: (intercept) | B2: 0.11313338 | C2: 0.12030434 | D2: 0.067579553 | E2: -0.11148895 | F2: -0.23265952 | G2: 0.043131193
A3: 15 | B3: -0.11800527 | C3: -0.20279155 | D3: -0.13290228 | E3: 0.30368804 | F3: 0.29001788 | G3: -0.14000682
A4: 15 sort | B4: -0.085387626 | C4: -0.16628659 | D4: -0.11810785 | E4: -0.64931252 | F4: 1.10992 | G4: -0.090825393
A5: 25 | B5: -0.49846714 | C5: -0.23161641 | D5: -0.22925172 | E5: 0.58504556 | F5: -0.041432395 | G5: 0.41572211
A6: 48 | B6: -0.066213456 | C6: -0.091080706 | D6: -0.064642748 | E6: 0.9562233 | F6: -0.095525261 | G6: -0.63876113
A7: 60 | B7: -0.072286316 | C7: -0.12288428 | D7: -0.13280291 | E7: 0.56884538 | F7: -0.11869832 | G7: -0.12217356
A8: abroad | B8: -0.353794 | C8: -0.29943676 | D8: -0.70653058 | E8: -0.21479698 | F8: 1.8539889 | G8: -0.27943057
A9: abroad log | B9: -0.12414422 | C9: -0.11621712 | D9: -0.060422132 | E9: -0.12308754 | F9: 0.56964681 | G9: -0.14577579
A10: abroad want | B10: -0.056548409 | C10: -0.038970456 | D10: -0.024520797 | E10: -0.064318135 | F10: 0.23109577 | G10: -0.046737973
A11: acceptable | B11: 0.93389421 | C11: -1.1471004 | D11: 0.55119392 | E11: -0.79170866 | F11: 0.18454783 | G11: 0.2691731
A12: access | B12: 2.4962363 | C12: -0.90554412 | D12: -0.23025322 | E12: -0.71884005 | F12: -0.59205938 | G12: -0.049539515
A13: access account | B13: 1.71405 | C13: -0.48389953 | D13: -0.027098233 | E13: -0.53440106 | F13: -0.38677683 | G13: -0.28187432
... A821: years webchat | B821: -0.20617171 | C821: 1.1312113 | D821: -0.17288282 | E821: -0.52176441 | F821: -0.11013433 | G821: -0.12025802

Sheet Scored
A1: complaint_id | B1: text | C1: true_label | D1: clean_text | E1: Fraud & Scams | F1: Mis-selling | G1: Account Access | H1: Fees & Charges | I1: Delays & Processing | J1: Customer Service | K1: exact_label | L1: Fraud & Scams | M1: Mis-selling | N1: Account Access | O1: Fees & Charges | P1: Delays & Processing | Q1: Customer Service | R1: fuzzy_label | S1: Account Access | T1: Customer Service | U1: Delays & Processing | V1: Fees & Charges | W1: Fraud & Scams | X1: Mis-selling | Y1: learned_label | Z1: used_for
A2: =Complaints!A2 -> C0001 | B2: =Complaints!B2 -> I was told this policy overed me but my claim was rejected. Also, the complaints handler was unhelpful and talked over me. This is not acceptable. | C2: =Complaints!C2 -> Mis-selling | D2: =" "&TRIM(SUBSTITUTE(SUBSTITUTE(SUBSTITUTE(SUBSTITUTE(SUBSTITUTE(SUBSTITUTE(SUBSTITUTE(SUBSTITUTE(SUBSTITUTE(SUBSTITUTE(SUBSTITUTE(SUBSTITUTE(SUBSTITUTE(SUBSTITUTE(SUBSTITUTE(SUBSTITUTE(LOWER(B2),"."," "),","," "),"'"," "),"’"," "),"!"," "),"?"," "),";"," "),":"," "),"-"," "),"("," "),")"," "),"""", " "),"£"," "),"&"," "),"/"," "),"%"," "))&" " -> i was told this policy overed me but my claim was rejected also the complaints handler was unhelpful and talked over me this is not acceptable | E2: =SUMPRODUCT((Rules!$A$2:$A$60=E$1)*Rules!$C$2:$C$60*ISNUMBER(SEARCH(Rules!$D$2:$D$60,$D2))) -> 0 | F2: =SUMPRODUCT((Rules!$A$2:$A$60=F$1)*Rules!$C$2:$C$60*ISNUMBER(SEARCH(Rules!$D$2:$D$60,$D2))) -> 1 | G2: =SUMPRODUCT((Rules!$A$2:$A$60=G$1)*Rules!$C$2:$C$60*ISNUMBER(SEARCH(Rules!$D$2:$D$60,$D2))) -> 0 | H2: =SUMPRODUCT((Rules!$A$2:$A$60=H$1)*Rules!$C$2:$C$60*ISNUMBER(SEARCH(Rules!$D$2:$D$60,$D2))) -> 0 | I2: =SUMPRODUCT((Rules!$A$2:$A$60=I$1)*Rules!$C$2:$C$60*ISNUMBER(SEARCH(Rules!$D$2:$D$60,$D2))) -> 0 | J2: =SUMPRODUCT((Rules!$A$2:$A$60=J$1)*Rules!$C$2:$C$60*ISNUMBER(SEARCH(Rules!$D$2:$D$60,$D2))) -> 2 | K2: =IF(OR(MAX(E2:J2)<Rules!$H$1,MAX(E2:J2)-LARGE(E2:J2,2)<Rules!$H$2),"No label",INDEX($E$1:$J$1,MATCH(MAX(E2:J2),E2:J2,0))) -> No label | L2: =SUMPRODUCT((Rules!$A$2:$A$60=L$1)*Rules!$C$2:$C$60*ISNUMBER(SEARCH(Rules!$E$2:$E$60,$D2))) -> 0 | M2: =SUMPRODUCT((Rules!$A$2:$A$60=M$1)*Rules!$C$2:$C$60*ISNUMBER(SEARCH(Rules!$E$2:$E$60,$D2))) -> 1 | N2: =SUMPRODUCT((Rules!$A$2:$A$60=N$1)*Rules!$C$2:$C$60*ISNUMBER(SEARCH(Rules!$E$2:$E$60,$D2))) -> 1 | O2: =SUMPRODUCT((Rules!$A$2:$A$60=O$1)*Rules!$C$2:$C$60*ISNUMBER(SEARCH(Rules!$E$2:$E$60,$D2))) -> 0 | P2: =SUMPRODUCT((Rules!$A$2:$A$60=P$1)*Rules!$C$2:$C$60*ISNUMBER(SEARCH(Rules!$E$2:$E$60,$D2))) -> 0 | Q2: =SUMPRODUCT((Rules!$A$2:$A$60=Q$1)*Rules!$C$2:$C$60*ISNUMBER(SEARCH(Rules!$E$2:$E$60,$D2))) -> 2 | R2: =IF(OR(MAX(L2:Q2)<Rules!$H$1,MAX(L2:Q2)-LARGE(L2:Q2,2)<Rules!$H$2),"No label",INDEX($L$1:$Q$1,MATCH(MAX(L2:Q2),L2:Q2,0))) -> No label | S2: =SUMPRODUCT(ISNUMBER(SEARCH(" "&Terms!$A$3:$A$821&" ",$D2))*Terms!B$3:B$821)+Terms!B$2 -> -1.808219 | T2: =SUMPRODUCT(ISNUMBER(SEARCH(" "&Terms!$A$3:$A$821&" ",$D2))*Terms!C$3:C$821)+Terms!C$2 -> 3.1860952 | U2: =SUMPRODUCT(ISNUMBER(SEARCH(" "&Terms!$A$3:$A$821&" ",$D2))*Terms!D$3:D$821)+Terms!D$2 -> -2.2421644 | V2: =SUMPRODUCT(ISNUMBER(SEARCH(" "&Terms!$A$3:$A$821&" ",$D2))*Terms!E$3:E$821)+Terms!E$2 -> -1.810709 | W2: =SUMPRODUCT(ISNUMBER(SEARCH(" "&Terms!$A$3:$A$821&" ",$D2))*Terms!F$3:F$821)+Terms!F$2 -> -3.6687543 | X2: =SUMPRODUCT(ISNUMBER(SEARCH(" "&Terms!$A$3:$A$821&" ",$D2))*Terms!G$3:G$821)+Terms!G$2 -> 6.3437516 | Y2: =INDEX($S$1:$X$1,MATCH(MAX(S2:X2),S2:X2,0)) -> Mis-selling | Z2: train
A3: =Complaints!A3 -> C0002 | B3: =Complaints!B3 -> Hello, I was told this policy covered me but my claim was rejected. I could not log in to check either. | C3: =Complaints!C3 -> Mis-selling | D3: =" "&TRIM(SUBSTITUTE(SUBSTITUTE(SUBSTITUTE(SUBSTITUTE(SUBSTITUTE(SUBSTITUTE(SUBSTITUTE(SUBSTITUTE(SUBSTITUTE(SUBSTITUTE(SUBSTITUTE(SUBSTITUTE(SUBSTITUTE(SUBSTITUTE(SUBSTITUTE(SUBSTITUTE(LOWER(B3),"."," "),","," "),"'"," "),"’"," "),"!"," "),"?"," "),";"," "),":"," "),"-"," "),"("," "),")"," "),"""", " "),"£"," "),"&"," "),"/"," "),"%"," "))&" " -> hello i was told this policy covered me but my claim was rejected i could not log in to check either | E3: =SUMPRODUCT((Rules!$A$2:$A$60=E$1)*Rules!$C$2:$C$60*ISNUMBER(SEARCH(Rules!$D$2:$D$60,$D3))) -> 0 | F3: =SUMPRODUCT((Rules!$A$2:$A$60=F$1)*Rules!$C$2:$C$60*ISNUMBER(SEARCH(Rules!$D$2:$D$60,$D3))) -> 1 | G3: =SUMPRODUCT((Rules!$A$2:$A$60=G$1)*Rules!$C$2:$C$60*ISNUMBER(SEARCH(Rules!$D$2:$D$60,$D3))) -> 3 | H3: =SUMPRODUCT((Rules!$A$2:$A$60=H$1)*Rules!$C$2:$C$60*ISNUMBER(SEARCH(Rules!$D$2:$D$60,$D3))) -> 0 | I3: =SUMPRODUCT((Rules!$A$2:$A$60=I$1)*Rules!$C$2:$C$60*ISNUMBER(SEARCH(Rules!$D$2:$D$60,$D3))) -> 0 | J3: =SUMPRODUCT((Rules!$A$2:$A$60=J$1)*Rules!$C$2:$C$60*ISNUMBER(SEARCH(Rules!$D$2:$D$60,$D3))) -> 0 | K3: =IF(OR(MAX(E3:J3)<Rules!$H$1,MAX(E3:J3)-LARGE(E3:J3,2)<Rules!$H$2),"No label",INDEX($E$1:$J$1,MATCH(MAX(E3:J3),E3:J3,0))) -> Account Access | L3: =SUMPRODUCT((Rules!$A$2:$A$60=L$1)*Rules!$C$2:$C$60*ISNUMBER(SEARCH(Rules!$E$2:$E$60,$D3))) -> 0 | M3: =SUMPRODUCT((Rules!$A$2:$A$60=M$1)*Rules!$C$2:$C$60*ISNUMBER(SEARCH(Rules!$E$2:$E$60,$D3))) -> 1 | N3: =SUMPRODUCT((Rules!$A$2:$A$60=N$1)*Rules!$C$2:$C$60*ISNUMBER(SEARCH(Rules!$E$2:$E$60,$D3))) -> 3 | O3: =SUMPRODUCT((Rules!$A$2:$A$60=O$1)*Rules!$C$2:$C$60*ISNUMBER(SEARCH(Rules!$E$2:$E$60,$D3))) -> 0 | P3: =SUMPRODUCT((Rules!$A$2:$A$60=P$1)*Rules!$C$2:$C$60*ISNUMBER(SEARCH(Rules!$E$2:$E$60,$D3))) -> 0 | Q3: =SUMPRODUCT((Rules!$A$2:$A$60=Q$1)*Rules!$C$2:$C$60*ISNUMBER(SEARCH(Rules!$E$2:$E$60,$D3))) -> 0 | R3: =IF(OR(MAX(L3:Q3)<Rules!$H$1,MAX(L3:Q3)-LARGE(L3:Q3,2)<Rules!$H$2),"No label",INDEX($L$1:$Q$1,MATCH(MAX(L3:Q3),L3:Q3,0))) -> Account Access | S3: =SUMPRODUCT(ISNUMBER(SEARCH(" "&Terms!$A$3:$A$821&" ",$D3))*Terms!B$3:B$821)+Terms!B$2 -> -2.0407343 | T3: =SUMPRODUCT(ISNUMBER(SEARCH(" "&Terms!$A$3:$A$821&" ",$D3))*Terms!C$3:C$821)+Terms!C$2 -> -3.8494774 | U3: =SUMPRODUCT(ISNUMBER(SEARCH(" "&Terms!$A$3:$A$821&" ",$D3))*Terms!D$3:D$821)+Terms!D$2 -> -0.25888779 | V3: =SUMPRODUCT(ISNUMBER(SEARCH(" "&Terms!$A$3:$A$821&" ",$D3))*Terms!E$3:E$821)+Terms!E$2 -> -0.095847823 | W3: =SUMPRODUCT(ISNUMBER(SEARCH(" "&Terms!$A$3:$A$821&" ",$D3))*Terms!F$3:F$821)+Terms!F$2 -> -2.715748 | X3: =SUMPRODUCT(ISNUMBER(SEARCH(" "&Terms!$A$3:$A$821&" ",$D3))*Terms!G$3:G$821)+Terms!G$2 -> 8.9606954 | Y3: =INDEX($S$1:$X$1,MATCH(MAX(S3:X3),S3:X3,0)) -> Mis-selling | Z3: train
A4: =Complaints!A4 -> C0003 | B4: =Complaints!B4 -> This is the second time I have raised this. The salesperson pushed me into a plan I did not need. I could not log in to check either. I would like a response in writing. | C4: =Complaints!C4 -> Mis-selling | D4: =" "&TRIM(SUBSTITUTE(SUBSTITUTE(SUBSTITUTE(SUBSTITUTE(SUBSTITUTE(SUBSTITUTE(SUBSTITUTE(SUBSTITUTE(SUBSTITUTE(SUBSTITUTE(SUBSTITUTE(SUBSTITUTE(SUBSTITUTE(SUBSTITUTE(SUBSTITUTE(SUBSTITUTE(LOWER(B4),"."," "),","," "),"'"," "),"’"," "),"!"," "),"?"," "),";"," "),":"," "),"-"," "),"("," "),")"," "),"""", " "),"£"," "),"&"," "),"/"," "),"%"," "))&" " -> this is the second time i have raised this the salesperson pushed me into a plan i did not need i could not log in to check either i would like a response in writing | E4: =SUMPRODUCT((Rules!$A$2:$A$60=E$1)*Rules!$C$2:$C$60*ISNUMBER(SEARCH(Rules!$D$2:$D$60,$D4))) -> 0 | F4: =SUMPRODUCT((Rules!$A$2:$A$60=F$1)*Rules!$C$2:$C$60*ISNUMBER(SEARCH(Rules!$D$2:$D$60,$D4))) -> 2 | G4: =SUMPRODUCT((Rules!$A$2:$A$60=G$1)*Rules!$C$2:$C$60*ISNUMBER(SEARCH(Rules!$D$2:$D$60,$D4))) -> 3 | H4: =SUMPRODUCT((Rules!$A$2:$A$60=H$1)*Rules!$C$2:$C$60*ISNUMBER(SEARCH(Rules!$D$2:$D$60,$D4))) -> 0 | I4: =SUMPRODUCT((Rules!$A$2:$A$60=I$1)*Rules!$C$2:$C$60*ISNUMBER(SEARCH(Rules!$D$2:$D$60,$D4))) -> 0 | J4: =SUMPRODUCT((Rules!$A$2:$A$60=J$1)*Rules!$C$2:$C$60*ISNUMBER(SEARCH(Rules!$D$2:$D$60,$D4))) -> 0 | K4: =IF(OR(MAX(E4:J4)<Rules!$H$1,MAX(E4:J4)-LARGE(E4:J4,2)<Rules!$H$2),"No label",INDEX($E$1:$J$1,MATCH(MAX(E4:J4),E4:J4,0))) -> No label | L4: =SUMPRODUCT((Rules!$A$2:$A$60=L$1)*Rules!$C$2:$C$60*ISNUMBER(SEARCH(Rules!$E$2:$E$60,$D4))) -> 0 | M4: =SUMPRODUCT((Rules!$A$2:$A$60=M$1)*Rules!$C$2:$C$60*ISNUMBER(SEARCH(Rules!$E$2:$E$60,$D4))) -> 2 | N4: =SUMPRODUCT((Rules!$A$2:$A$60=N$1)*Rules!$C$2:$C$60*ISNUMBER(SEARCH(Rules!$E$2:$E$60,$D4))) -> 3 | O4: =SUMPRODUCT((Rules!$A$2:$A$60=O$1)*Rules!$C$2:$C$60*ISNUMBER(SEARCH(Rules!$E$2:$E$60,$D4))) -> 0 | P4: =SUMPRODUCT((Rules!$A$2:$A$60=P$1)*Rules!$C$2:$C$60*ISNUMBER(SEARCH(Rules!$E$2:$E$60,$D4))) -> 0 | Q4: =SUMPRODUCT((Rules!$A$2:$A$60=Q$1)*Rules!$C$2:$C$60*ISNUMBER(SEARCH(Rules!$E$2:$E$60,$D4))) -> 0 | R4: =IF(OR(MAX(L4:Q4)<Rules!$H$1,MAX(L4:Q4)-LARGE(L4:Q4,2)<Rules!$H$2),"No label",INDEX($L$1:$Q$1,MATCH(MAX(L4:Q4),L4:Q4,0))) -> No label | S4: =SUMPRODUCT(ISNUMBER(SEARCH(" "&Terms!$A$3:$A$821&" ",$D4))*Terms!B$3:B$821)+Terms!B$2 -> -5.0113828 | T4: =SUMPRODUCT(ISNUMBER(SEARCH(" "&Terms!$A$3:$A$821&" ",$D4))*Terms!C$3:C$821)+Terms!C$2 -> 1.8317824 | U4: =SUMPRODUCT(ISNUMBER(SEARCH(" "&Terms!$A$3:$A$821&" ",$D4))*Terms!D$3:D$821)+Terms!D$2 -> -4.3497859 | V4: =SUMPRODUCT(ISNUMBER(SEARCH(" "&Terms!$A$3:$A$821&" ",$D4))*Terms!E$3:E$821)+Terms!E$2 -> -2.158725 | W4: =SUMPRODUCT(ISNUMBER(SEARCH(" "&Terms!$A$3:$A$821&" ",$D4))*Terms!F$3:F$821)+Terms!F$2 -> -0.37311685 | X4: =SUMPRODUCT(ISNUMBER(SEARCH(" "&Terms!$A$3:$A$821&" ",$D4))*Terms!G$3:G$821)+Terms!G$2 -> 10.061228 | Y4: =INDEX($S$1:$X$1,MATCH(MAX(S4:X4),S4:X4,0)) -> Mis-selling | Z4: test
A5: =Complaints!A5 -> C0004 | B5: =Complaints!B5 -> I am writing to complain. It has taken six weeks to process my claim and nobody has updated me. Please sort this out. | C5: =Complaints!C5 -> Delays & Processing | D5: =" "&TRIM(SUBSTITUTE(SUBSTITUTE(SUBSTITUTE(SUBSTITUTE(SUBSTITUTE(SUBSTITUTE(SUBSTITUTE(SUBSTITUTE(SUBSTITUTE(SUBSTITUTE(SUBSTITUTE(SUBSTITUTE(SUBSTITUTE(SUBSTITUTE(SUBSTITUTE(SUBSTITUTE(LOWER(B5),"."," "),","," "),"'"," "),"’"," "),"!"," "),"?"," "),";"," "),":"," "),"-"," "),"("," "),")"," "),"""", " "),"£"," "),"&"," "),"/"," "),"%"," "))&" " -> i am writing to complain it has taken six weeks to process my claim and nobody has updated me please sort this out | E5: =SUMPRODUCT((Rules!$A$2:$A$60=E$1)*Rules!$C$2:$C$60*ISNUMBER(SEARCH(Rules!$D$2:$D$60,$D5))) -> 0 | F5: =SUMPRODUCT((Rules!$A$2:$A$60=F$1)*Rules!$C$2:$C$60*ISNUMBER(SEARCH(Rules!$D$2:$D$60,$D5))) -> 0 | G5: =SUMPRODUCT((Rules!$A$2:$A$60=G$1)*Rules!$C$2:$C$60*ISNUMBER(SEARCH(Rules!$D$2:$D$60,$D5))) -> 0 | H5: =SUMPRODUCT((Rules!$A$2:$A$60=H$1)*Rules!$C$2:$C$60*ISNUMBER(SEARCH(Rules!$D$2:$D$60,$D5))) -> 0 | I5: =SUMPRODUCT((Rules!$A$2:$A$60=I$1)*Rules!$C$2:$C$60*ISNUMBER(SEARCH(Rules!$D$2:$D$60,$D5))) -> 2 | J5: =SUMPRODUCT((Rules!$A$2:$A$60=J$1)*Rules!$C$2:$C$60*ISNUMBER(SEARCH(Rules!$D$2:$D$60,$D5))) -> 0 | K5: =IF(OR(MAX(E5:J5)<Rules!$H$1,MAX(E5:J5)-LARGE(E5:J5,2)<Rules!$H$2),"No label",INDEX($E$1:$J$1,MATCH(MAX(E5:J5),E5:J5,0))) -> No label | L5: =SUMPRODUCT((Rules!$A$2:$A$60=L$1)*Rules!$C$2:$C$60*ISNUMBER(SEARCH(Rules!$E$2:$E$60,$D5))) -> 0 | M5: =SUMPRODUCT((Rules!$A$2:$A$60=M$1)*Rules!$C$2:$C$60*ISNUMBER(SEARCH(Rules!$E$2:$E$60,$D5))) -> 0 | N5: =SUMPRODUCT((Rules!$A$2:$A$60=N$1)*Rules!$C$2:$C$60*ISNUMBER(SEARCH(Rules!$E$2:$E$60,$D5))) -> 0 | O5: =SUMPRODUCT((Rules!$A$2:$A$60=O$1)*Rules!$C$2:$C$60*ISNUMBER(SEARCH(Rules!$E$2:$E$60,$D5))) -> 0 | P5: =SUMPRODUCT((Rules!$A$2:$A$60=P$1)*Rules!$C$2:$C$60*ISNUMBER(SEARCH(Rules!$E$2:$E$60,$D5))) -> 2 | Q5: =SUMPRODUCT((Rules!$A$2:$A$60=Q$1)*Rules!$C$2:$C$60*ISNUMBER(SEARCH(Rules!$E$2:$E$60,$D5))) -> 0 | R5: =IF(OR(MAX(L5:Q5)<Rules!$H$1,MAX(L5:Q5)-LARGE(L5:Q5,2)<Rules!$H$2),"No label",INDEX($L$1:$Q$1,MATCH(MAX(L5:Q5),L5:Q5,0))) -> No label | S5: =SUMPRODUCT(ISNUMBER(SEARCH(" "&Terms!$A$3:$A$821&" ",$D5))*Terms!B$3:B$821)+Terms!B$2 -> -4.3986271 | T5: =SUMPRODUCT(ISNUMBER(SEARCH(" "&Terms!$A$3:$A$821&" ",$D5))*Terms!C$3:C$821)+Terms!C$2 -> -1.3731389 | U5: =SUMPRODUCT(ISNUMBER(SEARCH(" "&Terms!$A$3:$A$821&" ",$D5))*Terms!D$3:D$821)+Terms!D$2 -> 9.3322713 | V5: =SUMPRODUCT(ISNUMBER(SEARCH(" "&Terms!$A$3:$A$821&" ",$D5))*Terms!E$3:E$821)+Terms!E$2 -> -0.83324316 | W5: =SUMPRODUCT(ISNUMBER(SEARCH(" "&Terms!$A$3:$A$821&" ",$D5))*Terms!F$3:F$821)+Terms!F$2 -> -1.2260073 | X5: =SUMPRODUCT(ISNUMBER(SEARCH(" "&Terms!$A$3:$A$821&" ",$D5))*Terms!G$3:G$821)+Terms!G$2 -> -1.5012549 | Y5: =INDEX($S$1:$X$1,MATCH(MAX(S5:X5),S5:X5,0)) -> Delays & Processing | Z5: train
A6: =Complaints!A6 -> C0005 | B6: =Complaints!B6 -> My mortgage switch is taking far longer than you said it would. Please escalate this. | C6: =Complaints!C6 -> Delays & Processing | D6: =" "&TRIM(SUBSTITUTE(SUBSTITUTE(SUBSTITUTE(SUBSTITUTE(SUBSTITUTE(SUBSTITUTE(SUBSTITUTE(SUBSTITUTE(SUBSTITUTE(SUBSTITUTE(SUBSTITUTE(SUBSTITUTE(SUBSTITUTE(SUBSTITUTE(SUBSTITUTE(SUBSTITUTE(LOWER(B6),"."," "),","," "),"'"," "),"’"," "),"!"," "),"?"," "),";"," "),":"," "),"-"," "),"("," "),")"," "),"""", " "),"£"," "),"&"," "),"/"," "),"%"," "))&" " -> my mortgage switch is taking far longer than you said it would please escalate this | E6: =SUMPRODUCT((Rules!$A$2:$A$60=E$1)*Rules!$C$2:$C$60*ISNUMBER(SEARCH(Rules!$D$2:$D$60,$D6))) -> 0 | F6: =SUMPRODUCT((Rules!$A$2:$A$60=F$1)*Rules!$C$2:$C$60*ISNUMBER(SEARCH(Rules!$D$2:$D$60,$D6))) -> 0 | G6: =SUMPRODUCT((Rules!$A$2:$A$60=G$1)*Rules!$C$2:$C$60*ISNUMBER(SEARCH(Rules!$D$2:$D$60,$D6))) -> 0 | H6: =SUMPRODUCT((Rules!$A$2:$A$60=H$1)*Rules!$C$2:$C$60*ISNUMBER(SEARCH(Rules!$D$2:$D$60,$D6))) -> 0 | I6: =SUMPRODUCT((Rules!$A$2:$A$60=I$1)*Rules!$C$2:$C$60*ISNUMBER(SEARCH(Rules!$D$2:$D$60,$D6))) -> 2 | J6: =SUMPRODUCT((Rules!$A$2:$A$60=J$1)*Rules!$C$2:$C$60*ISNUMBER(SEARCH(Rules!$D$2:$D$60,$D6))) -> 0 | K6: =IF(OR(MAX(E6:J6)<Rules!$H$1,MAX(E6:J6)-LARGE(E6:J6,2)<Rules!$H$2),"No label",INDEX($E$1:$J$1,MATCH(MAX(E6:J6),E6:J6,0))) -> No label | L6: =SUMPRODUCT((Rules!$A$2:$A$60=L$1)*Rules!$C$2:$C$60*ISNUMBER(SEARCH(Rules!$E$2:$E$60,$D6))) -> 0 | M6: =SUMPRODUCT((Rules!$A$2:$A$60=M$1)*Rules!$C$2:$C$60*ISNUMBER(SEARCH(Rules!$E$2:$E$60,$D6))) -> 0 | N6: =SUMPRODUCT((Rules!$A$2:$A$60=N$1)*Rules!$C$2:$C$60*ISNUMBER(SEARCH(Rules!$E$2:$E$60,$D6))) -> 0 | O6: =SUMPRODUCT((Rules!$A$2:$A$60=O$1)*Rules!$C$2:$C$60*ISNUMBER(SEARCH(Rules!$E$2:$E$60,$D6))) -> 0 | P6: =SUMPRODUCT((Rules!$A$2:$A$60=P$1)*Rules!$C$2:$C$60*ISNUMBER(SEARCH(Rules!$E$2:$E$60,$D6))) -> 2 | Q6: =SUMPRODUCT((Rules!$A$2:$A$60=Q$1)*Rules!$C$2:$C$60*ISNUMBER(SEARCH(Rules!$E$2:$E$60,$D6))) -> 0 | R6: =IF(OR(MAX(L6:Q6)<Rules!$H$1,MAX(L6:Q6)-LARGE(L6:Q6,2)<Rules!$H$2),"No label",INDEX($L$1:$Q$1,MATCH(MAX(L6:Q6),L6:Q6,0))) -> No label | S6: =SUMPRODUCT(ISNUMBER(SEARCH(" "&Terms!$A$3:$A$821&" ",$D6))*Terms!B$3:B$821)+Terms!B$2 -> -4.029266 | T6: =SUMPRODUCT(ISNUMBER(SEARCH(" "&Terms!$A$3:$A$821&" ",$D6))*Terms!C$3:C$821)+Terms!C$2 -> -0.16334693 | U6: =SUMPRODUCT(ISNUMBER(SEARCH(" "&Terms!$A$3:$A$821&" ",$D6))*Terms!D$3:D$821)+Terms!D$2 -> 9.9684063 | V6: =SUMPRODUCT(ISNUMBER(SEARCH(" "&Terms!$A$3:$A$821&" ",$D6))*Terms!E$3:E$821)+Terms!E$2 -> -1.5313725 | W6: =SUMPRODUCT(ISNUMBER(SEARCH(" "&Terms!$A$3:$A$821&" ",$D6))*Terms!F$3:F$821)+Terms!F$2 -> -2.5591675 | X6: =SUMPRODUCT(ISNUMBER(SEARCH(" "&Terms!$A$3:$A$821&" ",$D6))*Terms!G$3:G$821)+Terms!G$2 -> -1.6852533 | Y6: =INDEX($S$1:$X$1,MATCH(MAX(S6:X6),S6:X6,0)) -> Delays & Processing | Z6: train
A7: =Complaints!A7 -> C0006 | B7: =Complaints!B7 -> Hello, The app crashes every time I try to open my statements. There was also a fee involved. I expect compensation. | C7: =Complaints!C7 -> Account Access | D7: =" "&TRIM(SUBSTITUTE(SUBSTITUTE(SUBSTITUTE(SUBSTITUTE(SUBSTITUTE(SUBSTITUTE(SUBSTITUTE(SUBSTITUTE(SUBSTITUTE(SUBSTITUTE(SUBSTITUTE(SUBSTITUTE(SUBSTITUTE(SUBSTITUTE(SUBSTITUTE(SUBSTITUTE(LOWER(B7),"."," "),","," "),"'"," "),"’"," "),"!"," "),"?"," "),";"," "),":"," "),"-"," "),"("," "),")"," "),"""", " "),"£"," "),"&"," "),"/"," "),"%"," "))&" " -> hello the app crashes every time i try to open my statements there was also a fee involved i expect compensation | E7: =SUMPRODUCT((Rules!$A$2:$A$60=E$1)*Rules!$C$2:$C$60*ISNUMBER(SEARCH(Rules!$D$2:$D$60,$D7))) -> 0 | F7: =SUMPRODUCT((Rules!$A$2:$A$60=F$1)*Rules!$C$2:$C$60*ISNUMBER(SEARCH(Rules!$D$2:$D$60,$D7))) -> 0 | G7: =SUMPRODUCT((Rules!$A$2:$A$60=G$1)*Rules!$C$2:$C$60*ISNUMBER(SEARCH(Rules!$D$2:$D$60,$D7))) -> 3 | H7: =SUMPRODUCT((Rules!$A$2:$A$60=H$1)*Rules!$C$2:$C$60*ISNUMBER(SEARCH(Rules!$D$2:$D$60,$D7))) -> 2 | I7: =SUMPRODUCT((Rules!$A$2:$A$60=I$1)*Rules!$C$2:$C$60*ISNUMBER(SEARCH(Rules!$D$2:$D$60,$D7))) -> 0 | J7: =SUMPRODUCT((Rules!$A$2:$A$60=J$1)*Rules!$C$2:$C$60*ISNUMBER(SEARCH(Rules!$D$2:$D$60,$D7))) -> 0 | K7: =IF(OR(MAX(E7:J7)<Rules!$H$1,MAX(E7:J7)-LARGE(E7:J7,2)<Rules!$H$2),"No label",INDEX($E$1:$J$1,MATCH(MAX(E7:J7),E7:J7,0))) -> No label | L7: =SUMPRODUCT((Rules!$A$2:$A$60=L$1)*Rules!$C$2:$C$60*ISNUMBER(SEARCH(Rules!$E$2:$E$60,$D7))) -> 0 | M7: =SUMPRODUCT((Rules!$A$2:$A$60=M$1)*Rules!$C$2:$C$60*ISNUMBER(SEARCH(Rules!$E$2:$E$60,$D7))) -> 0 | N7: =SUMPRODUCT((Rules!$A$2:$A$60=N$1)*Rules!$C$2:$C$60*ISNUMBER(SEARCH(Rules!$E$2:$E$60,$D7))) -> 3 | O7: =SUMPRODUCT((Rules!$A$2:$A$60=O$1)*Rules!$C$2:$C$60*ISNUMBER(SEARCH(Rules!$E$2:$E$60,$D7))) -> 3 | P7: =SUMPRODUCT((Rules!$A$2:$A$60=P$1)*Rules!$C$2:$C$60*ISNUMBER(SEARCH(Rules!$E$2:$E$60,$D7))) -> 0 | Q7: =SUMPRODUCT((Rules!$A$2:$A$60=Q$1)*Rules!$C$2:$C$60*ISNUMBER(SEARCH(Rules!$E$2:$E$60,$D7))) -> 0 | R7: =IF(OR(MAX(L7:Q7)<Rules!$H$1,MAX(L7:Q7)-LARGE(L7:Q7,2)<Rules!$H$2),"No label",INDEX($L$1:$Q$1,MATCH(MAX(L7:Q7),L7:Q7,0))) -> No label | S7: =SUMPRODUCT(ISNUMBER(SEARCH(" "&Terms!$A$3:$A$821&" ",$D7))*Terms!B$3:B$821)+Terms!B$2 -> 12.317498 | T7: =SUMPRODUCT(ISNUMBER(SEARCH(" "&Terms!$A$3:$A$821&" ",$D7))*Terms!C$3:C$821)+Terms!C$2 -> -2.2342487 | U7: =SUMPRODUCT(ISNUMBER(SEARCH(" "&Terms!$A$3:$A$821&" ",$D7))*Terms!D$3:D$821)+Terms!D$2 -> -4.803688 | V7: =SUMPRODUCT(ISNUMBER(SEARCH(" "&Terms!$A$3:$A$821&" ",$D7))*Terms!E$3:E$821)+Terms!E$2 -> 1.0608173 | W7: =SUMPRODUCT(ISNUMBER(SEARCH(" "&Terms!$A$3:$A$821&" ",$D7))*Terms!F$3:F$821)+Terms!F$2 -> -2.2647843 | X7: =SUMPRODUCT(ISNUMBER(SEARCH(" "&Terms!$A$3:$A$821&" ",$D7))*Terms!G$3:G$821)+Terms!G$2 -> -4.075594 | Y7: =INDEX($S$1:$X$1,MATCH(MAX(S7:X7),S7:X7,0)) -> Account Access | Z7: train
A8: =Complaints!A8 -> C0007 | B8: =Complaints!B8 -> This is the second time I have raised this. The brochure said guaranteed returns and my money has lost value. I also spent ages on hold when I called about it. Please sort this out. | C8: =Complaints!C8 -> Mis-selling | D8: =" "&TRIM(SUBSTITUTE(SUBSTITUTE(SUBSTITUTE(SUBSTITUTE(SUBSTITUTE(SUBSTITUTE(SUBSTITUTE(SUBSTITUTE(SUBSTITUTE(SUBSTITUTE(SUBSTITUTE(SUBSTITUTE(SUBSTITUTE(SUBSTITUTE(SUBSTITUTE(SUBSTITUTE(LOWER(B8),"."," "),","," "),"'"," "),"’"," "),"!"," "),"?"," "),";"," "),":"," "),"-"," "),"("," "),")"," "),"""", " "),"£"," "),"&"," "),"/"," "),"%"," "))&" " -> this is the second time i have raised this the brochure said guaranteed returns and my money has lost value i also spent ages on hold when i called about it please sort this out | E8: =SUMPRODUCT((Rules!$A$2:$A$60=E$1)*Rules!$C$2:$C$60*ISNUMBER(SEARCH(Rules!$D$2:$D$60,$D8))) -> 0 | F8: =SUMPRODUCT((Rules!$A$2:$A$60=F$1)*Rules!$C$2:$C$60*ISNUMBER(SEARCH(Rules!$D$2:$D$60,$D8))) -> 2 | G8: =SUMPRODUCT((Rules!$A$2:$A$60=G$1)*Rules!$C$2:$C$60*ISNUMBER(SEARCH(Rules!$D$2:$D$60,$D8))) -> 0 | H8: =SUMPRODUCT((Rules!$A$2:$A$60=H$1)*Rules!$C$2:$C$60*ISNUMBER(SEARCH(Rules!$D$2:$D$60,$D8))) -> 0 | I8: =SUMPRODUCT((Rules!$A$2:$A$60=I$1)*Rules!$C$2:$C$60*ISNUMBER(SEARCH(Rules!$D$2:$D$60,$D8))) -> 0 | J8: =SUMPRODUCT((Rules!$A$2:$A$60=J$1)*Rules!$C$2:$C$60*ISNUMBER(SEARCH(Rules!$D$2:$D$60,$D8))) -> 3 | K8: =IF(OR(MAX(E8:J8)<Rules!$H$1,MAX(E8:J8)-LARGE(E8:J8,2)<Rules!$H$2),"No label",INDEX($E$1:$J$1,MATCH(MAX(E8:J8),E8:J8,0))) -> No label | L8: =SUMPRODUCT((Rules!$A$2:$A$60=L$1)*Rules!$C$2:$C$60*ISNUMBER(SEARCH(Rules!$E$2:$E$60,$D8))) -> 0 | M8: =SUMPRODUCT((Rules!$A$2:$A$60=M$1)*Rules!$C$2:$C$60*ISNUMBER(SEARCH(Rules!$E$2:$E$60,$D8))) -> 2 | N8: =SUMPRODUCT((Rules!$A$2:$A$60=N$1)*Rules!$C$2:$C$60*ISNUMBER(SEARCH(Rules!$E$2:$E$60,$D8))) -> 0 | O8: =SUMPRODUCT((Rules!$A$2:$A$60=O$1)*Rules!$C$2:$C$60*ISNUMBER(SEARCH(Rules!$E$2:$E$60,$D8))) -> 0 | P8: =SUMPRODUCT((Rules!$A$2:$A$60=P$1)*Rules!$C$2:$C$60*ISNUMBER(SEARCH(Rules!$E$2:$E$60,$D8))) -> 0 | Q8: =SUMPRODUCT((Rules!$A$2:$A$60=Q$1)*Rules!$C$2:$C$60*ISNUMBER(SEARCH(Rules!$E$2:$E$60,$D8))) -> 3 | R8: =IF(OR(MAX(L8:Q8)<Rules!$H$1,MAX(L8:Q8)-LARGE(L8:Q8,2)<Rules!$H$2),"No label",INDEX($L$1:$Q$1,MATCH(MAX(L8:Q8),L8:Q8,0))) -> No label | S8: =SUMPRODUCT(ISNUMBER(SEARCH(" "&Terms!$A$3:$A$821&" ",$D8))*Terms!B$3:B$821)+Terms!B$2 -> -8.5300404 | T8: =SUMPRODUCT(ISNUMBER(SEARCH(" "&Terms!$A$3:$A$821&" ",$D8))*Terms!C$3:C$821)+Terms!C$2 -> 0.063134175 | U8: =SUMPRODUCT(ISNUMBER(SEARCH(" "&Terms!$A$3:$A$821&" ",$D8))*Terms!D$3:D$821)+Terms!D$2 -> -1.5410999 | V8: =SUMPRODUCT(ISNUMBER(SEARCH(" "&Terms!$A$3:$A$821&" ",$D8))*Terms!E$3:E$821)+Terms!E$2 -> -3.029994 | W8: =SUMPRODUCT(ISNUMBER(SEARCH(" "&Terms!$A$3:$A$821&" ",$D8))*Terms!F$3:F$821)+Terms!F$2 -> 0.93712748 | X8: =SUMPRODUCT(ISNUMBER(SEARCH(" "&Terms!$A$3:$A$821&" ",$D8))*Terms!G$3:G$821)+Terms!G$2 -> 12.100873 | Y8: =INDEX($S$1:$X$1,MATCH(MAX(S8:X8),S8:X8,0)) -> Mis-selling | Z8: train
A9: =Complaints!A9 -> C0008 | B9: =Complaints!B9 -> This is the second time I have raised this. I asked for a callback and it never happened. I would like a response in writing. | C9: =Complaints!C9 -> Customer Service | D9: =" "&TRIM(SUBSTITUTE(SUBSTITUTE(SUBSTITUTE(SUBSTITUTE(SUBSTITUTE(SUBSTITUTE(SUBSTITUTE(SUBSTITUTE(SUBSTITUTE(SUBSTITUTE(SUBSTITUTE(SUBSTITUTE(SUBSTITUTE(SUBSTITUTE(SUBSTITUTE(SUBSTITUTE(LOWER(B9),"."," "),","," "),"'"," "),"’"," "),"!"," "),"?"," "),";"," "),":"," "),"-"," "),"("," "),")"," "),"""", " "),"£"," "),"&"," "),"/"," "),"%"," "))&" " -> this is the second time i have raised this i asked for a callback and it never happened i would like a response in writing | E9: =SUMPRODUCT((Rules!$A$2:$A$60=E$1)*Rules!$C$2:$C$60*ISNUMBER(SEARCH(Rules!$D$2:$D$60,$D9))) -> 0 | F9: =SUMPRODUCT((Rules!$A$2:$A$60=F$1)*Rules!$C$2:$C$60*ISNUMBER(SEARCH(Rules!$D$2:$D$60,$D9))) -> 0 | G9: =SUMPRODUCT((Rules!$A$2:$A$60=G$1)*Rules!$C$2:$C$60*ISNUMBER(SEARCH(Rules!$D$2:$D$60,$D9))) -> 0 | H9: =SUMPRODUCT((Rules!$A$2:$A$60=H$1)*Rules!$C$2:$C$60*ISNUMBER(SEARCH(Rules!$D$2:$D$60,$D9))) -> 0 | I9: =SUMPRODUCT((Rules!$A$2:$A$60=I$1)*Rules!$C$2:$C$60*ISNUMBER(SEARCH(Rules!$D$2:$D$60,$D9))) -> 0 | J9: =SUMPRODUCT((Rules!$A$2:$A$60=J$1)*Rules!$C$2:$C$60*ISNUMBER(SEARCH(Rules!$D$2:$D$60,$D9))) -> 2 | K9: =IF(OR(MAX(E9:J9)<Rules!$H$1,MAX(E9:J9)-LARGE(E9:J9,2)<Rules!$H$2),"No label",INDEX($E$1:$J$1,MATCH(MAX(E9:J9),E9:J9,0))) -> No label | L9: =SUMPRODUCT((Rules!$A$2:$A$60=L$1)*Rules!$C$2:$C$60*ISNUMBER(SEARCH(Rules!$E$2:$E$60,$D9))) -> 0 | M9: =SUMPRODUCT((Rules!$A$2:$A$60=M$1)*Rules!$C$2:$C$60*ISNUMBER(SEARCH(Rules!$E$2:$E$60,$D9))) -> 0 | N9: =SUMPRODUCT((Rules!$A$2:$A$60=N$1)*Rules!$C$2:$C$60*ISNUMBER(SEARCH(Rules!$E$2:$E$60,$D9))) -> 0 | O9: =SUMPRODUCT((Rules!$A$2:$A$60=O$1)*Rules!$C$2:$C$60*ISNUMBER(SEARCH(Rules!$E$2:$E$60,$D9))) -> 0 | P9: =SUMPRODUCT((Rules!$A$2:$A$60=P$1)*Rules!$C$2:$C$60*ISNUMBER(SEARCH(Rules!$E$2:$E$60,$D9))) -> 0 | Q9: =SUMPRODUCT((Rules!$A$2:$A$60=Q$1)*Rules!$C$2:$C$60*ISNUMBER(SEARCH(Rules!$E$2:$E$60,$D9))) -> 2 | R9: =IF(OR(MAX(L9:Q9)<Rules!$H$1,MAX(L9:Q9)-LARGE(L9:Q9,2)<Rules!$H$2),"No label",INDEX($L$1:$Q$1,MATCH(MAX(L9:Q9),L9:Q9,0))) -> No label | S9: =SUMPRODUCT(ISNUMBER(SEARCH(" "&Terms!$A$3:$A$821&" ",$D9))*Terms!B$3:B$821)+Terms!B$2 -> -2.9940245 | T9: =SUMPRODUCT(ISNUMBER(SEARCH(" "&Terms!$A$3:$A$821&" ",$D9))*Terms!C$3:C$821)+Terms!C$2 -> 6.8180726 | U9: =SUMPRODUCT(ISNUMBER(SEARCH(" "&Terms!$A$3:$A$821&" ",$D9))*Terms!D$3:D$821)+Terms!D$2 -> -3.1056253 | V9: =SUMPRODUCT(ISNUMBER(SEARCH(" "&Terms!$A$3:$A$821&" ",$D9))*Terms!E$3:E$821)+Terms!E$2 -> -0.81905926 | W9: =SUMPRODUCT(ISNUMBER(SEARCH(" "&Terms!$A$3:$A$821&" ",$D9))*Terms!F$3:F$821)+Terms!F$2 -> -1.1029095 | X9: =SUMPRODUCT(ISNUMBER(SEARCH(" "&Terms!$A$3:$A$821&" ",$D9))*Terms!G$3:G$821)+Terms!G$2 -> 1.203546 | Y9: =INDEX($S$1:$X$1,MATCH(MAX(S9:X9),S9:X9,0)) -> Customer Service | Z9: train
A10: =Complaints!A10 -> C0009 | B10: =Complaints!B10 -> I am writing to complain. Why has my interest rate gone up without notice, it is costing me more every month. | C10: =Complaints!C10 -> Fees & Charges | D10: =" "&TRIM(SUBSTITUTE(SUBSTITUTE(SUBSTITUTE(SUBSTITUTE(SUBSTITUTE(SUBSTITUTE(SUBSTITUTE(SUBSTITUTE(SUBSTITUTE(SUBSTITUTE(SUBSTITUTE(SUBSTITUTE(SUBSTITUTE(SUBSTITUTE(SUBSTITUTE(SUBSTITUTE(LOWER(B10),"."," "),","," "),"'"," "),"’"," "),"!"," "),"?"," "),";"," "),":"," "),"-"," "),"("," "),")"," "),"""", " "),"£"," "),"&"," "),"/"," "),"%"," "))&" " -> i am writing to complain why has my interest rate gone up without notice it is costing me more every month | E10: =SUMPRODUCT((Rules!$A$2:$A$60=E$1)*Rules!$C$2:$C$60*ISNUMBER(SEARCH(Rules!$D$2:$D$60,$D10))) -> 0 | F10: =SUMPRODUCT((Rules!$A$2:$A$60=F$1)*Rules!$C$2:$C$60*ISNUMBER(SEARCH(Rules!$D$2:$D$60,$D10))) -> 0 | G10: =SUMPRODUCT((Rules!$A$2:$A$60=G$1)*Rules!$C$2:$C$60*ISNUMBER(SEARCH(Rules!$D$2:$D$60,$D10))) -> 0 | H10: =SUMPRODUCT((Rules!$A$2:$A$60=H$1)*Rules!$C$2:$C$60*ISNUMBER(SEARCH(Rules!$D$2:$D$60,$D10))) -> 2 | I10: =SUMPRODUCT((Rules!$A$2:$A$60=I$1)*Rules!$C$2:$C$60*ISNUMBER(SEARCH(Rules!$D$2:$D$60,$D10))) -> 0 | J10: =SUMPRODUCT((Rules!$A$2:$A$60=J$1)*Rules!$C$2:$C$60*ISNUMBER(SEARCH(Rules!$D$2:$D$60,$D10))) -> 0 | K10: =IF(OR(MAX(E10:J10)<Rules!$H$1,MAX(E10:J10)-LARGE(E10:J10,2)<Rules!$H$2),"No label",INDEX($E$1:$J$1,MATCH(MAX(E10:J10),E10:J10,0))) -> No label | L10: =SUMPRODUCT((Rules!$A$2:$A$60=L$1)*Rules!$C$2:$C$60*ISNUMBER(SEARCH(Rules!$E$2:$E$60,$D10))) -> 0 | M10: =SUMPRODUCT((Rules!$A$2:$A$60=M$1)*Rules!$C$2:$C$60*ISNUMBER(SEARCH(Rules!$E$2:$E$60,$D10))) -> 0 | N10: =SUMPRODUCT((Rules!$A$2:$A$60=N$1)*Rules!$C$2:$C$60*ISNUMBER(SEARCH(Rules!$E$2:$E$60,$D10))) -> 0 | O10: =SUMPRODUCT((Rules!$A$2:$A$60=O$1)*Rules!$C$2:$C$60*ISNUMBER(SEARCH(Rules!$E$2:$E$60,$D10))) -> 2 | P10: =SUMPRODUCT((Rules!$A$2:$A$60=P$1)*Rules!$C$2:$C$60*ISNUMBER(SEARCH(Rules!$E$2:$E$60,$D10))) -> 0 | Q10: =SUMPRODUCT((Rules!$A$2:$A$60=Q$1)*Rules!$C$2:$C$60*ISNUMBER(SEARCH(Rules!$E$2:$E$60,$D10))) -> 0 | R10: =IF(OR(MAX(L10:Q10)<Rules!$H$1,MAX(L10:Q10)-LARGE(L10:Q10,2)<Rules!$H$2),"No label",INDEX($L$1:$Q$1,MATCH(MAX(L10:Q10),L10:Q10,0))) -> No label | S10: =SUMPRODUCT(ISNUMBER(SEARCH(" "&Terms!$A$3:$A$821&" ",$D10))*Terms!B$3:B$821)+Terms!B$2 -> -1.1329448 | T10: =SUMPRODUCT(ISNUMBER(SEARCH(" "&Terms!$A$3:$A$821&" ",$D10))*Terms!C$3:C$821)+Terms!C$2 -> -1.3591113 | U10: =SUMPRODUCT(ISNUMBER(SEARCH(" "&Terms!$A$3:$A$821&" ",$D10))*Terms!D$3:D$821)+Terms!D$2 -> 1.659465 | V10: =SUMPRODUCT(ISNUMBER(SEARCH(" "&Terms!$A$3:$A$821&" ",$D10))*Terms!E$3:E$821)+Terms!E$2 -> 5.5240109 | W10: =SUMPRODUCT(ISNUMBER(SEARCH(" "&Terms!$A$3:$A$821&" ",$D10))*Terms!F$3:F$821)+Terms!F$2 -> -2.1333954 | X10: =SUMPRODUCT(ISNUMBER(SEARCH(" "&Terms!$A$3:$A$821&" ",$D10))*Terms!G$3:G$821)+Terms!G$2 -> -2.5580245 | Y10: =INDEX($S$1:$X$1,MATCH(MAX(S10:X10),S10:X10,0)) -> Fees & Charges | Z10: test
A11: =Complaints!A11 -> C0010 | B11: =Complaints!B11 -> To whom it may concern, Someone has made payments from my account that I did not authorise. Also, the app crashes every time I try to open my statements. Please escalate this. | C11: =Complaints!C11 -> Fraud & Scams | D11: =" "&TRIM(SUBSTITUTE(SUBSTITUTE(SUBSTITUTE(SUBSTITUTE(SUBSTITUTE(SUBSTITUTE(SUBSTITUTE(SUBSTITUTE(SUBSTITUTE(SUBSTITUTE(SUBSTITUTE(SUBSTITUTE(SUBSTITUTE(SUBSTITUTE(SUBSTITUTE(SUBSTITUTE(LOWER(B11),"."," "),","," "),"'"," "),"’"," "),"!"," "),"?"," "),";"," "),":"," "),"-"," "),"("," "),")"," "),"""", " "),"£"," "),"&"," "),"/"," "),"%"," "))&" " -> to whom it may concern someone has made payments from my account that i did not authorise also the app crashes every time i try to open my statements please escalate this | E11: =SUMPRODUCT((Rules!$A$2:$A$60=E$1)*Rules!$C$2:$C$60*ISNUMBER(SEARCH(Rules!$D$2:$D$60,$D11))) -> 3 | F11: =SUMPRODUCT((Rules!$A$2:$A$60=F$1)*Rules!$C$2:$C$60*ISNUMBER(SEARCH(Rules!$D$2:$D$60,$D11))) -> 0 | G11: =SUMPRODUCT((Rules!$A$2:$A$60=G$1)*Rules!$C$2:$C$60*ISNUMBER(SEARCH(Rules!$D$2:$D$60,$D11))) -> 3 | H11: =SUMPRODUCT((Rules!$A$2:$A$60=H$1)*Rules!$C$2:$C$60*ISNUMBER(SEARCH(Rules!$D$2:$D$60,$D11))) -> 0 | I11: =SUMPRODUCT((Rules!$A$2:$A$60=I$1)*Rules!$C$2:$C$60*ISNUMBER(SEARCH(Rules!$D$2:$D$60,$D11))) -> 0 | J11: =SUMPRODUCT((Rules!$A$2:$A$60=J$1)*Rules!$C$2:$C$60*ISNUMBER(SEARCH(Rules!$D$2:$D$60,$D11))) -> 0 | K11: =IF(OR(MAX(E11:J11)<Rules!$H$1,MAX(E11:J11)-LARGE(E11:J11,2)<Rules!$H$2),"No label",INDEX($E$1:$J$1,MATCH(MAX(E11:J11),E11:J11,0))) -> No label | L11: =SUMPRODUCT((Rules!$A$2:$A$60=L$1)*Rules!$C$2:$C$60*ISNUMBER(SEARCH(Rules!$E$2:$E$60,$D11))) -> 3 | M11: =SUMPRODUCT((Rules!$A$2:$A$60=M$1)*Rules!$C$2:$C$60*ISNUMBER(SEARCH(Rules!$E$2:$E$60,$D11))) -> 0 | N11: =SUMPRODUCT((Rules!$A$2:$A$60=N$1)*Rules!$C$2:$C$60*ISNUMBER(SEARCH(Rules!$E$2:$E$60,$D11))) -> 3 | O11: =SUMPRODUCT((Rules!$A$2:$A$60=O$1)*Rules!$C$2:$C$60*ISNUMBER(SEARCH(Rules!$E$2:$E$60,$D11))) -> 1 | P11: =SUMPRODUCT((Rules!$A$2:$A$60=P$1)*Rules!$C$2:$C$60*ISNUMBER(SEARCH(Rules!$E$2:$E$60,$D11))) -> 0 | Q11: =SUMPRODUCT((Rules!$A$2:$A$60=Q$1)*Rules!$C$2:$C$60*ISNUMBER(SEARCH(Rules!$E$2:$E$60,$D11))) -> 0 | R11: =IF(OR(MAX(L11:Q11)<Rules!$H$1,MAX(L11:Q11)-LARGE(L11:Q11,2)<Rules!$H$2),"No label",INDEX($L$1:$Q$1,MATCH(MAX(L11:Q11),L11:Q11,0))) -> No label | S11: =SUMPRODUCT(ISNUMBER(SEARCH(" "&Terms!$A$3:$A$821&" ",$D11))*Terms!B$3:B$821)+Terms!B$2 -> 9.9443376 | T11: =SUMPRODUCT(ISNUMBER(SEARCH(" "&Terms!$A$3:$A$821&" ",$D11))*Terms!C$3:C$821)+Terms!C$2 -> -2.119985 | U11: =SUMPRODUCT(ISNUMBER(SEARCH(" "&Terms!$A$3:$A$821&" ",$D11))*Terms!D$3:D$821)+Terms!D$2 -> -2.9405774 | V11: =SUMPRODUCT(ISNUMBER(SEARCH(" "&Terms!$A$3:$A$821&" ",$D11))*Terms!E$3:E$821)+Terms!E$2 -> -1.2232305 | W11: =SUMPRODUCT(ISNUMBER(SEARCH(" "&Terms!$A$3:$A$821&" ",$D11))*Terms!F$3:F$821)+Terms!F$2 -> 0.88969573 | X11: =SUMPRODUCT(ISNUMBER(SEARCH(" "&Terms!$A$3:$A$821&" ",$D11))*Terms!G$3:G$821)+Terms!G$2 -> -4.5502404 | Y11: =INDEX($S$1:$X$1,MATCH(MAX(S11:X11),S11:X11,0)) -> Account Access | Z11: test
A12: =Complaints!A12 -> C0011 | B12: =Complaints!B12 -> I was tricked into moving savings to a safe account that was not safe. Also, my account was frozen and I cannot get in to move money. | C12: =Complaints!C12 -> Fraud & Scams | D12: =" "&TRIM(SUBSTITUTE(SUBSTITUTE(SUBSTITUTE(SUBSTITUTE(SUBSTITUTE(SUBSTITUTE(SUBSTITUTE(SUBSTITUTE(SUBSTITUTE(SUBSTITUTE(SUBSTITUTE(SUBSTITUTE(SUBSTITUTE(SUBSTITUTE(SUBSTITUTE(SUBSTITUTE(LOWER(B12),"."," "),","," "),"'"," "),"’"," "),"!"," "),"?"," "),";"," "),":"," "),"-"," "),"("," "),")"," "),"""", " "),"£"," "),"&"," "),"/"," "),"%"," "))&" " -> i was tricked into moving savings to a safe account that was not safe also my account was frozen and i cannot get in to move money | E12: =SUMPRODUCT((Rules!$A$2:$A$60=E$1)*Rules!$C$2:$C$60*ISNUMBER(SEARCH(Rules!$D$2:$D$60,$D12))) -> 2 | F12: =SUMPRODUCT((Rules!$A$2:$A$60=F$1)*Rules!$C$2:$C$60*ISNUMBER(SEARCH(Rules!$D$2:$D$60,$D12))) -> 0 | G12: =SUMPRODUCT((Rules!$A$2:$A$60=G$1)*Rules!$C$2:$C$60*ISNUMBER(SEARCH(Rules!$D$2:$D$60,$D12))) -> 0 | H12: =SUMPRODUCT((Rules!$A$2:$A$60=H$1)*Rules!$C$2:$C$60*ISNUMBER(SEARCH(Rules!$D$2:$D$60,$D12))) -> 0 | I12: =SUMPRODUCT((Rules!$A$2:$A$60=I$1)*Rules!$C$2:$C$60*ISNUMBER(SEARCH(Rules!$D$2:$D$60,$D12))) -> 0 | J12: =SUMPRODUCT((Rules!$A$2:$A$60=J$1)*Rules!$C$2:$C$60*ISNUMBER(SEARCH(Rules!$D$2:$D$60,$D12))) -> 0 | K12: =IF(OR(MAX(E12:J12)<Rules!$H$1,MAX(E12:J12)-LARGE(E12:J12,2)<Rules!$H$2),"No label",INDEX($E$1:$J$1,MATCH(MAX(E12:J12),E12:J12,0))) -> No label | L12: =SUMPRODUCT((Rules!$A$2:$A$60=L$1)*Rules!$C$2:$C$60*ISNUMBER(SEARCH(Rules!$E$2:$E$60,$D12))) -> 2 | M12: =SUMPRODUCT((Rules!$A$2:$A$60=M$1)*Rules!$C$2:$C$60*ISNUMBER(SEARCH(Rules!$E$2:$E$60,$D12))) -> 0 | N12: =SUMPRODUCT((Rules!$A$2:$A$60=N$1)*Rules!$C$2:$C$60*ISNUMBER(SEARCH(Rules!$E$2:$E$60,$D12))) -> 0 | O12: =SUMPRODUCT((Rules!$A$2:$A$60=O$1)*Rules!$C$2:$C$60*ISNUMBER(SEARCH(Rules!$E$2:$E$60,$D12))) -> 0 | P12: =SUMPRODUCT((Rules!$A$2:$A$60=P$1)*Rules!$C$2:$C$60*ISNUMBER(SEARCH(Rules!$E$2:$E$60,$D12))) -> 0 | Q12: =SUMPRODUCT((Rules!$A$2:$A$60=Q$1)*Rules!$C$2:$C$60*ISNUMBER(SEARCH(Rules!$E$2:$E$60,$D12))) -> 0 | R12: =IF(OR(MAX(L12:Q12)<Rules!$H$1,MAX(L12:Q12)-LARGE(L12:Q12,2)<Rules!$H$2),"No label",INDEX($L$1:$Q$1,MATCH(MAX(L12:Q12),L12:Q12,0))) -> No label | S12: =SUMPRODUCT(ISNUMBER(SEARCH(" "&Terms!$A$3:$A$821&" ",$D12))*Terms!B$3:B$821)+Terms!B$2 -> 1.7887804 | T12: =SUMPRODUCT(ISNUMBER(SEARCH(" "&Terms!$A$3:$A$821&" ",$D12))*Terms!C$3:C$821)+Terms!C$2 -> -7.3211617 | U12: =SUMPRODUCT(ISNUMBER(SEARCH(" "&Terms!$A$3:$A$821&" ",$D12))*Terms!D$3:D$821)+Terms!D$2 -> 0.68519991 | V12: =SUMPRODUCT(ISNUMBER(SEARCH(" "&Terms!$A$3:$A$821&" ",$D12))*Terms!E$3:E$821)+Terms!E$2 -> -2.0017905 | W12: =SUMPRODUCT(ISNUMBER(SEARCH(" "&Terms!$A$3:$A$821&" ",$D12))*Terms!F$3:F$821)+Terms!F$2 -> 10.341915 | X12: =SUMPRODUCT(ISNUMBER(SEARCH(" "&Terms!$A$3:$A$821&" ",$D12))*Terms!G$3:G$821)+Terms!G$2 -> -3.4929428 | Y12: =INDEX($S$1:$X$1,MATCH(MAX(S12:X12),S12:X12,0)) -> Fraud & Scams | Z12: train
A13: =Complaints!A13 -> C0012 | B13: =Complaints!B13 -> I asked for a callback and it never happened. | C13: =Complaints!C13 -> Customer Service | D13: =" "&TRIM(SUBSTITUTE(SUBSTITUTE(SUBSTITUTE(SUBSTITUTE(SUBSTITUTE(SUBSTITUTE(SUBSTITUTE(SUBSTITUTE(SUBSTITUTE(SUBSTITUTE(SUBSTITUTE(SUBSTITUTE(SUBSTITUTE(SUBSTITUTE(SUBSTITUTE(SUBSTITUTE(LOWER(B13),"."," "),","," "),"'"," "),"’"," "),"!"," "),"?"," "),";"," "),":"," "),"-"," "),"("," "),")"," "),"""", " "),"£"," "),"&"," "),"/"," "),"%"," "))&" " -> i asked for a callback and it never happened | E13: =SUMPRODUCT((Rules!$A$2:$A$60=E$1)*Rules!$C$2:$C$60*ISNUMBER(SEARCH(Rules!$D$2:$D$60,$D13))) -> 0 | F13: =SUMPRODUCT((Rules!$A$2:$A$60=F$1)*Rules!$C$2:$C$60*ISNUMBER(SEARCH(Rules!$D$2:$D$60,$D13))) -> 0 | G13: =SUMPRODUCT((Rules!$A$2:$A$60=G$1)*Rules!$C$2:$C$60*ISNUMBER(SEARCH(Rules!$D$2:$D$60,$D13))) -> 0 | H13: =SUMPRODUCT((Rules!$A$2:$A$60=H$1)*Rules!$C$2:$C$60*ISNUMBER(SEARCH(Rules!$D$2:$D$60,$D13))) -> 0 | I13: =SUMPRODUCT((Rules!$A$2:$A$60=I$1)*Rules!$C$2:$C$60*ISNUMBER(SEARCH(Rules!$D$2:$D$60,$D13))) -> 0 | J13: =SUMPRODUCT((Rules!$A$2:$A$60=J$1)*Rules!$C$2:$C$60*ISNUMBER(SEARCH(Rules!$D$2:$D$60,$D13))) -> 2 | K13: =IF(OR(MAX(E13:J13)<Rules!$H$1,MAX(E13:J13)-LARGE(E13:J13,2)<Rules!$H$2),"No label",INDEX($E$1:$J$1,MATCH(MAX(E13:J13),E13:J13,0))) -> No label | L13: =SUMPRODUCT((Rules!$A$2:$A$60=L$1)*Rules!$C$2:$C$60*ISNUMBER(SEARCH(Rules!$E$2:$E$60,$D13))) -> 0 | M13: =SUMPRODUCT((Rules!$A$2:$A$60=M$1)*Rules!$C$2:$C$60*ISNUMBER(SEARCH(Rules!$E$2:$E$60,$D13))) -> 0 | N13: =SUMPRODUCT((Rules!$A$2:$A$60=N$1)*Rules!$C$2:$C$60*ISNUMBER(SEARCH(Rules!$E$2:$E$60,$D13))) -> 0 | O13: =SUMPRODUCT((Rules!$A$2:$A$60=O$1)*Rules!$C$2:$C$60*ISNUMBER(SEARCH(Rules!$E$2:$E$60,$D13))) -> 0 | P13: =SUMPRODUCT((Rules!$A$2:$A$60=P$1)*Rules!$C$2:$C$60*ISNUMBER(SEARCH(Rules!$E$2:$E$60,$D13))) -> 0 | Q13: =SUMPRODUCT((Rules!$A$2:$A$60=Q$1)*Rules!$C$2:$C$60*ISNUMBER(SEARCH(Rules!$E$2:$E$60,$D13))) -> 2 | R13: =IF(OR(MAX(L13:Q13)<Rules!$H$1,MAX(L13:Q13)-LARGE(L13:Q13,2)<Rules!$H$2),"No label",INDEX($L$1:$Q$1,MATCH(MAX(L13:Q13),L13:Q13,0))) -> No label | S13: =SUMPRODUCT(ISNUMBER(SEARCH(" "&Terms!$A$3:$A$821&" ",$D13))*Terms!B$3:B$821)+Terms!B$2 -> -1.3511719 | T13: =SUMPRODUCT(ISNUMBER(SEARCH(" "&Terms!$A$3:$A$821&" ",$D13))*Terms!C$3:C$821)+Terms!C$2 -> 5.2550407 | U13: =SUMPRODUCT(ISNUMBER(SEARCH(" "&Terms!$A$3:$A$821&" ",$D13))*Terms!D$3:D$821)+Terms!D$2 -> -2.3292027 | V13: =SUMPRODUCT(ISNUMBER(SEARCH(" "&Terms!$A$3:$A$821&" ",$D13))*Terms!E$3:E$821)+Terms!E$2 -> -0.62018547 | W13: =SUMPRODUCT(ISNUMBER(SEARCH(" "&Terms!$A$3:$A$821&" ",$D13))*Terms!F$3:F$821)+Terms!F$2 -> -0.76708795 | X13: =SUMPRODUCT(ISNUMBER(SEARCH(" "&Terms!$A$3:$A$821&" ",$D13))*Terms!G$3:G$821)+Terms!G$2 -> -0.18739261 | Y13: =INDEX($S$1:$X$1,MATCH(MAX(S13:X13),S13:X13,0)) -> Customer Service | Z13: train
... A901: =Complaints!A901 -> C0900 | B901: =Complaints!B901 -> Hello, I spent an hour on hold and then the call was cut off. Also, the account maintenance fee was taken twice this month. | C901: =Complaints!C901 -> Customer Service | D901: =" "&TRIM(SUBSTITUTE(SUBSTITUTE(SUBSTITUTE(SUBSTITUTE(SUBSTITUTE(SUBSTITUTE(SUBSTITUTE(SUBSTITUTE(SUBSTITUTE(SUBSTITUTE(SUBSTITUTE(SUBSTITUTE(SUBSTITUTE(SUBSTITUTE(SUBSTITUTE(SUBSTITUTE(LOWER(B901),"."," "),","," "),"'"," "),"’"," "),"!"," "),"?"," "),";"," "),":"," "),"-"," "),"("," "),")"," "),"""", " "),"£"," "),"&"," "),"/"," "),"%"," "))&" " -> hello i spent an hour on hold and then the call was cut off also the account maintenance fee was taken twice this month | E901: =SUMPRODUCT((Rules!$A$2:$A$60=E$1)*Rules!$C$2:$C$60*ISNUMBER(SEARCH(Rules!$D$2:$D$60,$D901))) -> 0 | F901: =SUMPRODUCT((Rules!$A$2:$A$60=F$1)*Rules!$C$2:$C$60*ISNUMBER(SEARCH(Rules!$D$2:$D$60,$D901))) -> 0 | G901: =SUMPRODUCT((Rules!$A$2:$A$60=G$1)*Rules!$C$2:$C$60*ISNUMBER(SEARCH(Rules!$D$2:$D$60,$D901))) -> 0 | H901: =SUMPRODUCT((Rules!$A$2:$A$60=H$1)*Rules!$C$2:$C$60*ISNUMBER(SEARCH(Rules!$D$2:$D$60,$D901))) -> 2 | I901: =SUMPRODUCT((Rules!$A$2:$A$60=I$1)*Rules!$C$2:$C$60*ISNUMBER(SEARCH(Rules!$D$2:$D$60,$D901))) -> 0 | J901: =SUMPRODUCT((Rules!$A$2:$A$60=J$1)*Rules!$C$2:$C$60*ISNUMBER(SEARCH(Rules!$D$2:$D$60,$D901))) -> 3 | K901: =IF(OR(MAX(E901:J901)<Rules!$H$1,MAX(E901:J901)-LARGE(E901:J901,2)<Rules!$H$2),"No label",INDEX($E$1:$J$1,MATCH(MAX(E901:J901),E901:J901,0))) -> No label | L901: =SUMPRODUCT((Rules!$A$2:$A$60=L$1)*Rules!$C$2:$C$60*ISNUMBER(SEARCH(Rules!$E$2:$E$60,$D901))) -> 0 | M901: =SUMPRODUCT((Rules!$A$2:$A$60=M$1)*Rules!$C$2:$C$60*ISNUMBER(SEARCH(Rules!$E$2:$E$60,$D901))) -> 0 | N901: =SUMPRODUCT((Rules!$A$2:$A$60=N$1)*Rules!$C$2:$C$60*ISNUMBER(SEARCH(Rules!$E$2:$E$60,$D901))) -> 0 | O901: =SUMPRODUCT((Rules!$A$2:$A$60=O$1)*Rules!$C$2:$C$60*ISNUMBER(SEARCH(Rules!$E$2:$E$60,$D901))) -> 2 | P901: =SUMPRODUCT((Rules!$A$2:$A$60=P$1)*Rules!$C$2:$C$60*ISNUMBER(SEARCH(Rules!$E$2:$E$60,$D901))) -> 0 | Q901: =SUMPRODUCT((Rules!$A$2:$A$60=Q$1)*Rules!$C$2:$C$60*ISNUMBER(SEARCH(Rules!$E$2:$E$60,$D901))) -> 3 | R901: =IF(OR(MAX(L901:Q901)<Rules!$H$1,MAX(L901:Q901)-LARGE(L901:Q901,2)<Rules!$H$2),"No label",INDEX($L$1:$Q$1,MATCH(MAX(L901:Q901),L901:Q901,0))) -> No label | S901: =SUMPRODUCT(ISNUMBER(SEARCH(" "&Terms!$A$3:$A$821&" ",$D901))*Terms!B$3:B$821)+Terms!B$2 -> -1.883654 | T901: =SUMPRODUCT(ISNUMBER(SEARCH(" "&Terms!$A$3:$A$821&" ",$D901))*Terms!C$3:C$821)+Terms!C$2 -> 4.2135813 | U901: =SUMPRODUCT(ISNUMBER(SEARCH(" "&Terms!$A$3:$A$821&" ",$D901))*Terms!D$3:D$821)+Terms!D$2 -> -2.5533032 | V901: =SUMPRODUCT(ISNUMBER(SEARCH(" "&Terms!$A$3:$A$821&" ",$D901))*Terms!E$3:E$821)+Terms!E$2 -> 8.9639487 | W901: =SUMPRODUCT(ISNUMBER(SEARCH(" "&Terms!$A$3:$A$821&" ",$D901))*Terms!F$3:F$821)+Terms!F$2 -> -3.0554111 | X901: =SUMPRODUCT(ISNUMBER(SEARCH(" "&Terms!$A$3:$A$821&" ",$D901))*Terms!G$3:G$821)+Terms!G$2 -> -5.6851617 | Y901: =INDEX($S$1:$X$1,MATCH(MAX(S901:X901),S901:X901,0)) -> Fees & Charges | Z901: train

Sheet NewComplaints
A1: complaint_id | B1: text
A2: N0001 | B2: To whom it may concern, The pension transfer advice I received was poor and I have lost out. Also, my card reader stopped working and I cannot approve payments.
A3: N0002 | B3: Hello, I was told this policy covered me but my claim was rejected. Also, i have been billed an annual fee I never agreed to. Please sort this out.
A4: N0003 | B4: I think I was the victim of a scam and sent money to a fraudster. Also, why has my interest rate gone up without notice, it is costing me more every month. I would like a response in writing.
A5: N0004 | B5: This is the second time I have raised this. I am unable to access my account to see my balance. I expect compensation.
A6: N0005 | B6: I have been a customer for years. A late payment fee appeared and I want it refunded. I do not think it was explained proprly when I bought it.
A7: N0006 | B7: I spent an hour on hold and then the call was cut off. There was also a fee involved. This is not acceptable.
A8: N0007 | B8: I was tricked into moving savings to a safe account that was not safe. Also, i cannot log in to the mobile app since the update.
A9: N0008 | B9: This is the second time I have raised this. I was advised to take out cover that duplicates what I already had. I want this put right.
A10: N0009 | B10: The paprwork was submitted a month ago and I am still waiting. There was also a fee involved. I expect compensation.
A11: N0010 | B11: To whom it may concern, I cannot log in to the mobile app since the update. I would like a response in writing.
A12: N0011 | B12: There are transactions on my card I do not recognise. Please sort this out.
... A201: N0200 | B201: This is the second time I have raised this. The app crashes every time I try to open my statements. I am worried it might be fraud.

Sheet Answers
A1: complaint_id | B1: true_label
A2: N0001 | B2: Mis-selling
A3: N0002 | B3: Mis-selling
A4: N0003 | B4: Fraud & Scams
A5: N0004 | B5: Account Access
A6: N0005 | B6: Fees & Charges
A7: N0006 | B7: Customer Service
A8: N0007 | B8: Fraud & Scams
A9: N0008 | B9: Mis-selling
A10: N0009 | B10: Delays & Processing
A11: N0010 | B11: Account Access
A12: N0011 | B12: Fraud & Scams
... A201: N0200 | B201: Account Access

Sheet New
A1: complaint_id | B1: text | C1: clean_text | D1: Fraud & Scams | E1: Mis-selling | F1: Account Access | G1: Fees & Charges | H1: Delays & Processing | I1: Customer Service | J1: exact_label | K1: Account Access | L1: Customer Service | M1: Delays & Processing | N1: Fees & Charges | O1: Fraud & Scams | P1: Mis-selling | Q1: learned_label | R1: final_label | S1: true_label | T1: final_correct
A2: =NewComplaints!A2 -> N0001 | B2: =NewComplaints!B2 -> To whom it may concern, The pension transfer advice I received was poor and I have lost out. Also, my card reader stopped working and I cannot approve payments. | C2: =" "&TRIM(SUBSTITUTE(SUBSTITUTE(SUBSTITUTE(SUBSTITUTE(SUBSTITUTE(SUBSTITUTE(SUBSTITUTE(SUBSTITUTE(SUBSTITUTE(SUBSTITUTE(SUBSTITUTE(SUBSTITUTE(SUBSTITUTE(SUBSTITUTE(SUBSTITUTE(SUBSTITUTE(LOWER(B2),"."," "),","," "),"'"," "),"’"," "),"!"," "),"?"," "),";"," "),":"," "),"-"," "),"("," "),")"," "),"""", " "),"£"," "),"&"," "),"/"," "),"%"," "))&" " -> to whom it may concern the pension transfer advice i received was poor and i have lost out also my card reader stopped working and i cannot approve payments | D2: =SUMPRODUCT((Rules!$A$2:$A$60=D$1)*Rules!$C$2:$C$60*ISNUMBER(SEARCH(Rules!$D$2:$D$60,$C2))) -> 0 | E2: =SUMPRODUCT((Rules!$A$2:$A$60=E$1)*Rules!$C$2:$C$60*ISNUMBER(SEARCH(Rules!$D$2:$D$60,$C2))) -> 2 | F2: =SUMPRODUCT((Rules!$A$2:$A$60=F$1)*Rules!$C$2:$C$60*ISNUMBER(SEARCH(Rules!$D$2:$D$60,$C2))) -> 0 | G2: =SUMPRODUCT((Rules!$A$2:$A$60=G$1)*Rules!$C$2:$C$60*ISNUMBER(SEARCH(Rules!$D$2:$D$60,$C2))) -> 0 | H2: =SUMPRODUCT((Rules!$A$2:$A$60=H$1)*Rules!$C$2:$C$60*ISNUMBER(SEARCH(Rules!$D$2:$D$60,$C2))) -> 0 | I2: =SUMPRODUCT((Rules!$A$2:$A$60=I$1)*Rules!$C$2:$C$60*ISNUMBER(SEARCH(Rules!$D$2:$D$60,$C2))) -> 0 | J2: =IF(OR(MAX(D2:I2)<Rules!$H$1,MAX(D2:I2)-LARGE(D2:I2,2)<Rules!$H$2),"No label",INDEX($D$1:$I$1,MATCH(MAX(D2:I2),D2:I2,0))) -> No label | K2: =SUMPRODUCT(ISNUMBER(SEARCH(" "&Terms!$A$3:$A$821&" ",$C2))*Terms!B$3:B$821)+Terms!B$2 -> 12.394761 | L2: =SUMPRODUCT(ISNUMBER(SEARCH(" "&Terms!$A$3:$A$821&" ",$C2))*Terms!C$3:C$821)+Terms!C$2 -> -2.8022806 | M2: =SUMPRODUCT(ISNUMBER(SEARCH(" "&Terms!$A$3:$A$821&" ",$C2))*Terms!D$3:D$821)+Terms!D$2 -> -1.2350059 | N2: =SUMPRODUCT(ISNUMBER(SEARCH(" "&Terms!$A$3:$A$821&" ",$C2))*Terms!E$3:E$821)+Terms!E$2 -> -6.315873 | O2: =SUMPRODUCT(ISNUMBER(SEARCH(" "&Terms!$A$3:$A$821&" ",$C2))*Terms!F$3:F$821)+Terms!F$2 -> -3.1372144 | P2: =SUMPRODUCT(ISNUMBER(SEARCH(" "&Terms!$A$3:$A$821&" ",$C2))*Terms!G$3:G$821)+Terms!G$2 -> 1.0956126 | Q2: =INDEX($K$1:$P$1,MATCH(MAX(K2:P2),K2:P2,0)) -> Account Access | R2: =IF(J2<>"No label",J2,Q2) -> Account Access | S2: =INDEX(Answers!$B$2:$B$201,MATCH(A2,Answers!$A$2:$A$201,0)) -> Mis-selling | T2: =R2=S2 -> FALSE
A3: =NewComplaints!A3 -> N0002 | B3: =NewComplaints!B3 -> Hello, I was told this policy covered me but my claim was rejected. Also, i have been billed an annual fee I never agreed to. Please sort this out. | C3: =" "&TRIM(SUBSTITUTE(SUBSTITUTE(SUBSTITUTE(SUBSTITUTE(SUBSTITUTE(SUBSTITUTE(SUBSTITUTE(SUBSTITUTE(SUBSTITUTE(SUBSTITUTE(SUBSTITUTE(SUBSTITUTE(SUBSTITUTE(SUBSTITUTE(SUBSTITUTE(SUBSTITUTE(LOWER(B3),"."," "),","," "),"'"," "),"’"," "),"!"," "),"?"," "),";"," "),":"," "),"-"," "),"("," "),")"," "),"""", " "),"£"," "),"&"," "),"/"," "),"%"," "))&" " -> hello i was told this policy covered me but my claim was rejected also i have been billed an annual fee i never agreed to please sort this out | D3: =SUMPRODUCT((Rules!$A$2:$A$60=D$1)*Rules!$C$2:$C$60*ISNUMBER(SEARCH(Rules!$D$2:$D$60,$C3))) -> 0 | E3: =SUMPRODUCT((Rules!$A$2:$A$60=E$1)*Rules!$C$2:$C$60*ISNUMBER(SEARCH(Rules!$D$2:$D$60,$C3))) -> 1 | F3: =SUMPRODUCT((Rules!$A$2:$A$60=F$1)*Rules!$C$2:$C$60*ISNUMBER(SEARCH(Rules!$D$2:$D$60,$C3))) -> 0 | G3: =SUMPRODUCT((Rules!$A$2:$A$60=G$1)*Rules!$C$2:$C$60*ISNUMBER(SEARCH(Rules!$D$2:$D$60,$C3))) -> 4 | H3: =SUMPRODUCT((Rules!$A$2:$A$60=H$1)*Rules!$C$2:$C$60*ISNUMBER(SEARCH(Rules!$D$2:$D$60,$C3))) -> 0 | I3: =SUMPRODUCT((Rules!$A$2:$A$60=I$1)*Rules!$C$2:$C$60*ISNUMBER(SEARCH(Rules!$D$2:$D$60,$C3))) -> 0 | J3: =IF(OR(MAX(D3:I3)<Rules!$H$1,MAX(D3:I3)-LARGE(D3:I3,2)<Rules!$H$2),"No label",INDEX($D$1:$I$1,MATCH(MAX(D3:I3),D3:I3,0))) -> Fees & Charges | K3: =SUMPRODUCT(ISNUMBER(SEARCH(" "&Terms!$A$3:$A$821&" ",$C3))*Terms!B$3:B$821)+Terms!B$2 -> -4.4850603 | L3: =SUMPRODUCT(ISNUMBER(SEARCH(" "&Terms!$A$3:$A$821&" ",$C3))*Terms!C$3:C$821)+Terms!C$2 -> -4.6103165 | M3: =SUMPRODUCT(ISNUMBER(SEARCH(" "&Terms!$A$3:$A$821&" ",$C3))*Terms!D$3:D$821)+Terms!D$2 -> -2.5971928 | N3: =SUMPRODUCT(ISNUMBER(SEARCH(" "&Terms!$A$3:$A$821&" ",$C3))*Terms!E$3:E$821)+Terms!E$2 -> 12.255669 | O3: =SUMPRODUCT(ISNUMBER(SEARCH(" "&Terms!$A$3:$A$821&" ",$C3))*Terms!F$3:F$821)+Terms!F$2 -> -7.0700111 | P3: =SUMPRODUCT(ISNUMBER(SEARCH(" "&Terms!$A$3:$A$821&" ",$C3))*Terms!G$3:G$821)+Terms!G$2 -> 6.5069116 | Q3: =INDEX($K$1:$P$1,MATCH(MAX(K3:P3),K3:P3,0)) -> Fees & Charges | R3: =IF(J3<>"No label",J3,Q3) -> Fees & Charges | S3: =INDEX(Answers!$B$2:$B$201,MATCH(A3,Answers!$A$2:$A$201,0)) -> Mis-selling | T3: =R3=S3 -> FALSE
A4: =NewComplaints!A4 -> N0003 | B4: =NewComplaints!B4 -> I think I was the victim of a scam and sent money to a fraudster. Also, why has my interest rate gone up without notice, it is costing me more every month. I would like a response in writing. | C4: =" "&TRIM(SUBSTITUTE(SUBSTITUTE(SUBSTITUTE(SUBSTITUTE(SUBSTITUTE(SUBSTITUTE(SUBSTITUTE(SUBSTITUTE(SUBSTITUTE(SUBSTITUTE(SUBSTITUTE(SUBSTITUTE(SUBSTITUTE(SUBSTITUTE(SUBSTITUTE(SUBSTITUTE(LOWER(B4),"."," "),","," "),"'"," "),"’"," "),"!"," "),"?"," "),";"," "),":"," "),"-"," "),"("," "),")"," "),"""", " "),"£"," "),"&"," "),"/"," "),"%"," "))&" " -> i think i was the victim of a scam and sent money to a fraudster also why has my interest rate gone up without notice it is costing me more every month i would like a response in writing | D4: =SUMPRODUCT((Rules!$A$2:$A$60=D$1)*Rules!$C$2:$C$60*ISNUMBER(SEARCH(Rules!$D$2:$D$60,$C4))) -> 6 | E4: =SUMPRODUCT((Rules!$A$2:$A$60=E$1)*Rules!$C$2:$C$60*ISNUMBER(SEARCH(Rules!$D$2:$D$60,$C4))) -> 0 | F4: =SUMPRODUCT((Rules!$A$2:$A$60=F$1)*Rules!$C$2:$C$60*ISNUMBER(SEARCH(Rules!$D$2:$D$60,$C4))) -> 0 | G4: =SUMPRODUCT((Rules!$A$2:$A$60=G$1)*Rules!$C$2:$C$60*ISNUMBER(SEARCH(Rules!$D$2:$D$60,$C4))) -> 2 | H4: =SUMPRODUCT((Rules!$A$2:$A$60=H$1)*Rules!$C$2:$C$60*ISNUMBER(SEARCH(Rules!$D$2:$D$60,$C4))) -> 0 | I4: =SUMPRODUCT((Rules!$A$2:$A$60=I$1)*Rules!$C$2:$C$60*ISNUMBER(SEARCH(Rules!$D$2:$D$60,$C4))) -> 0 | J4: =IF(OR(MAX(D4:I4)<Rules!$H$1,MAX(D4:I4)-LARGE(D4:I4,2)<Rules!$H$2),"No label",INDEX($D$1:$I$1,MATCH(MAX(D4:I4),D4:I4,0))) -> Fraud & Scams | K4: =SUMPRODUCT(ISNUMBER(SEARCH(" "&Terms!$A$3:$A$821&" ",$C4))*Terms!B$3:B$821)+Terms!B$2 -> -0.99615895 | L4: =SUMPRODUCT(ISNUMBER(SEARCH(" "&Terms!$A$3:$A$821&" ",$C4))*Terms!C$3:C$821)+Terms!C$2 -> -6.5347974 | M4: =SUMPRODUCT(ISNUMBER(SEARCH(" "&Terms!$A$3:$A$821&" ",$C4))*Terms!D$3:D$821)+Terms!D$2 -> -0.64682244 | N4: =SUMPRODUCT(ISNUMBER(SEARCH(" "&Terms!$A$3:$A$821&" ",$C4))*Terms!E$3:E$821)+Terms!E$2 -> 3.6509175 | O4: =SUMPRODUCT(ISNUMBER(SEARCH(" "&Terms!$A$3:$A$821&" ",$C4))*Terms!F$3:F$821)+Terms!F$2 -> 6.8164057 | P4: =SUMPRODUCT(ISNUMBER(SEARCH(" "&Terms!$A$3:$A$821&" ",$C4))*Terms!G$3:G$821)+Terms!G$2 -> -2.2895445 | Q4: =INDEX($K$1:$P$1,MATCH(MAX(K4:P4),K4:P4,0)) -> Fraud & Scams | R4: =IF(J4<>"No label",J4,Q4) -> Fraud & Scams | S4: =INDEX(Answers!$B$2:$B$201,MATCH(A4,Answers!$A$2:$A$201,0)) -> Fraud & Scams | T4: =R4=S4 -> TRUE
A5: =NewComplaints!A5 -> N0004 | B5: =NewComplaints!B5 -> This is the second time I have raised this. I am unable to access my account to see my balance. I expect compensation. | C5: =" "&TRIM(SUBSTITUTE(SUBSTITUTE(SUBSTITUTE(SUBSTITUTE(SUBSTITUTE(SUBSTITUTE(SUBSTITUTE(SUBSTITUTE(SUBSTITUTE(SUBSTITUTE(SUBSTITUTE(SUBSTITUTE(SUBSTITUTE(SUBSTITUTE(SUBSTITUTE(SUBSTITUTE(LOWER(B5),"."," "),","," "),"'"," "),"’"," "),"!"," "),"?"," "),";"," "),":"," "),"-"," "),"("," "),")"," "),"""", " "),"£"," "),"&"," "),"/"," "),"%"," "))&" " -> this is the second time i have raised this i am unable to access my account to see my balance i expect compensation | D5: =SUMPRODUCT((Rules!$A$2:$A$60=D$1)*Rules!$C$2:$C$60*ISNUMBER(SEARCH(Rules!$D$2:$D$60,$C5))) -> 0 | E5: =SUMPRODUCT((Rules!$A$2:$A$60=E$1)*Rules!$C$2:$C$60*ISNUMBER(SEARCH(Rules!$D$2:$D$60,$C5))) -> 0 | F5: =SUMPRODUCT((Rules!$A$2:$A$60=F$1)*Rules!$C$2:$C$60*ISNUMBER(SEARCH(Rules!$D$2:$D$60,$C5))) -> 1 | G5: =SUMPRODUCT((Rules!$A$2:$A$60=G$1)*Rules!$C$2:$C$60*ISNUMBER(SEARCH(Rules!$D$2:$D$60,$C5))) -> 0 | H5: =SUMPRODUCT((Rules!$A$2:$A$60=H$1)*Rules!$C$2:$C$60*ISNUMBER(SEARCH(Rules!$D$2:$D$60,$C5))) -> 0 | I5: =SUMPRODUCT((Rules!$A$2:$A$60=I$1)*Rules!$C$2:$C$60*ISNUMBER(SEARCH(Rules!$D$2:$D$60,$C5))) -> 0 | J5: =IF(OR(MAX(D5:I5)<Rules!$H$1,MAX(D5:I5)-LARGE(D5:I5,2)<Rules!$H$2),"No label",INDEX($D$1:$I$1,MATCH(MAX(D5:I5),D5:I5,0))) -> No label | K5: =SUMPRODUCT(ISNUMBER(SEARCH(" "&Terms!$A$3:$A$821&" ",$C5))*Terms!B$3:B$821)+Terms!B$2 -> 7.648921 | L5: =SUMPRODUCT(ISNUMBER(SEARCH(" "&Terms!$A$3:$A$821&" ",$C5))*Terms!C$3:C$821)+Terms!C$2 -> -2.689916 | M5: =SUMPRODUCT(ISNUMBER(SEARCH(" "&Terms!$A$3:$A$821&" ",$C5))*Terms!D$3:D$821)+Terms!D$2 -> -0.0089776586 | N5: =SUMPRODUCT(ISNUMBER(SEARCH(" "&Terms!$A$3:$A$821&" ",$C5))*Terms!E$3:E$821)+Terms!E$2 -> -1.3310282 | O5: =SUMPRODUCT(ISNUMBER(SEARCH(" "&Terms!$A$3:$A$821&" ",$C5))*Terms!F$3:F$821)+Terms!F$2 -> 1.2833335 | P5: =SUMPRODUCT(ISNUMBER(SEARCH(" "&Terms!$A$3:$A$821&" ",$C5))*Terms!G$3:G$821)+Terms!G$2 -> -4.9023326 | Q5: =INDEX($K$1:$P$1,MATCH(MAX(K5:P5),K5:P5,0)) -> Account Access | R5: =IF(J5<>"No label",J5,Q5) -> Account Access | S5: =INDEX(Answers!$B$2:$B$201,MATCH(A5,Answers!$A$2:$A$201,0)) -> Account Access | T5: =R5=S5 -> TRUE
